Workbook
Name gr_list_A: Lists!$A$2:$A$190
Name gr_list_AA: Lists!$A$2:$A$190
Name gr_list_B: Lists!$B$2:$B$19
Name gr_list_C: Lists!$C$2:$C$13
Name gr_list_D: Lists!$D$2:$D$3
Name gr_list_E: Lists!$E$2:$E$7
Name gr_list_F: Lists!$F$2:$F$31
Name gr_list_G: Lists!$G$2:$G$501
Name gr_list_H: Lists!$H$2:$H$8
Name gr_list_I: Lists!$I$2:$I$12
Name gr_list_J: Lists!$J$2:$J$11
Name gr_list_K: Lists!$K$2:$K$21
Name gr_list_L: Lists!$L$2:$L$31
Name gr_list_M: Lists!$M$2:$M$37

Sheet Read Me
A1: Garbage Rips 585 master sheet
A3: What this is | B3: The control surface for garbagerips.com. Everything the site knows that cannot be worked out from YouTube or the card database lives here. Fill in what you know, export, import, and the site changes.
A5: Grey columns | B5: From YouTube or the card database. Do not edit. Video ID and Key are what link a row to its video or card, so never edit those and never sort in a way that separates a row from them.
A6: Yellow columns | B6: Yours. Blank is fine everywhere: the import skips anything unanswered, so twenty rows at a time is a perfectly good way to work.
A7: Gold columns | B7: Hall of Fame and Most Wanted, the two things that change the top of the home page.
A8: Blue text | B8: A guess the site already made. Correct it if it is wrong, leave it if it is right. Black text means a person typed it.
A9: Dropdowns | B9: A shortcut, never a gate. Every one accepts anything you type, so a value missing from the list is never a reason you cannot record it.
A10: If the list looks short | B10: Google Sheets does not keep a dropdown that points at another tab. When you export back to xlsx it rebuilds each one from the values already in that column, so options nobody has used yet disappear. The Lists tab is the real list. Read it there and type the value in; it will be accepted.
A11: Hit Card is free text | B11: It has no dropdown here. If Sheets offers to make one out of what you have typed, decline it. If one appears anyway, select the column and use Data then Data validation then Remove rule.
A13: THE TABS
A14: Video Log | B14: Every video. Sets, opening type, the hit, the Hall of Fame, and per-video copy for the site.
A15: Set Notes | B15: The two facts the card database does not carry: whether a set is still in print, and what a pack costs. Set guides omit both until filled in.
A16: Chase Cards | B16: Every chase card on the site. PSA 10 prices live ONLY here: nothing can fetch a graded price, so this tab is the only route onto the site. Most Wanted marks a card for the hunt page and the home page band.
A17: Shops | B17: Local card shops for /shops.html.
A18: Summary | B18: Live counts of how much is filled in.
A19: Lists | B19: The source of every dropdown. Add a row here to add an option.
A21: HOW TO IMPORT | B21: Google Sheets exports the ACTIVE tab only, so open the tab you want first, then File > Download > Comma-separated values.
A22: Video Log | B22: node scripts/import-sheet.mjs <csv>
A23: Chase Cards | B23: node scripts/import-cards.mjs <csv>
A24: Shops | B24: node scripts/import-cards.mjs <csv>
B25: Either importer works out which tab it is from the header row, so the filename does not matter.
A27: The one that matters most | B27: Set. 61 videos have no set tag. A video with no set cannot be filtered and cannot reach the Hall of Fame. Eight of those are graded hits locked out of the home page right now.
A29: Packs from several sets | B29: A tin with two packs, or a box with ten packs from four sets, belongs to every set it contains. Name them all in Sets & Packs, commas between them, the set the video is really about first, and put the count next to the set it counts: 'First Partner Illustration Collection (Series 1) - 1 Pack, Phantasmal Flames - 1 Pack, Mega Evolution - 1 Pack'. The count belongs beside the name because that is the only place it cannot come adrift when you insert a set into the middle of the list later.
A31: How many packs | B31: The count in Sets & Packs is HOW MANY, Pack # is WHICH ONE, and they answer different questions. A video opening pack 3 of a nine-pack ETB is Pack # 3, and its Sets & Packs cell just names the set, because it opened one pack. Leaving the count off means one, so most rows never need it: you only write '- 2 Pack' when a video opened two of the same set, like the Abyss Eye video that ripped packs 9 and 10 back to back. Neither number is ever how many packs the box holds.
A33: Which one, and which pack | B33: Box # is which one of that product you are opening, counting your own openings of it from that set: your third Chaos Rising ETB is 3. Pack # is which pack out of it this video opens. Fill both in and the Chaos Rising guide can say how many ETBs, bundles and single packs have been opened from that set, which nothing else in the sheet can work out. Both are optional and blank is the normal case: a set with none recorded shows no counts at all rather than a zero.
A35: Greatest Hits | B35: Mark Yes on the RIPS you want in the gold section at the top of the home page. Rank orders them, 1 first. Leave Rank blank and the site orders by rarity then views. These are videos.
A37: Card Hall of Fame | B37: On the Chase Cards tab. Mark Yes on the CARDS you have actually pulled. They get their own page, ranked by value, with the card image, the set, the raw near mint price and the PSA 10 price. These are cards, not videos, which is the whole difference between the two.
A39: PSA 10 prices | B39: Put in a number you have actually seen, set PSA 10 Checked to the date you checked it (2026-08-11 format), and name the source. A graded price with no date is not a fact about anything, and a blank shows nothing rather than a guess.
A41: Careful | B41: Rebuilding this file overwrites it. Import your latest export FIRST, then rebuild. Anything already imported is carried back in; anything not is lost.

Sheet Lists
A1: Sets | B1: Opening Types | C1: Hit Rarities | D1: Yes/No | E1: Playlists | F1: Box / Series | G1: Hit Cards | H1: PSA 10 Sources | I1: Shop Areas | J1: Shop Good For | K1: HoF Ranks | L1: Box Numbers | M1: Pack Numbers
A2: Pitch Black | B2: Single Booster Pack | C2: Mega Hyper Rare | D2: Yes | E2: Greatest Hits | F2: Ascended Heroes 2-Pack Blister | G2: AZ's Tranquility | H2: PSA Price Guide | I2: Rochester, NY | J2: Sealed product | K2: 1 | L2: 1 | M2: 1
A3: Chaos Rising | B3: Booster Bundle | C3: Hyper Rare | D3: No | E3: Hits Only | F3: Ascended Heroes Booster Bundle | G3: Abra | H3: eBay sold listings | I3: Greece, NY | J3: Singles | K3: 2 | L3: 2 | M3: 2
A4: Perfect Order | B4: Booster Box | C4: Special Illustration Rare | E4: Full Box Openings | F4: Ascended Heroes ETB | G4: Accelgor | H4: 130point | I4: Henrietta, NY | J4: New releases | K4: 3 | L4: 3 | M4: 3
A5: Ascended Heroes | B5: ETB (Elite Trainer Box) | C5: Illustration Rare | E5: Singles | F5: Ascended Heroes ETB FINAL PACK | G5: Acerola's Mischief | H5: TCGplayer | I5: Irondequoit, NY | J5: In store | K5: 4 | L5: 4 | M5: 4
A6: Phantasmal Flames | B6: SPC (Super Premium Collection) | C6: Ultra Rare | E6: Japanese | F6: Ascended Heroes Elite Trainer Box | G6: Aipom | H6: PriceCharting | I6: Brighton, NY | J6: Graded slabs | K6: 5 | L6: 5 | M6: 5
A7: Mega Evolution | B7: UPC (Ultra Premium Collection) | C7: Double Rare | E7: None | F7: Ascended Heroes Mini Tin | G7: Alakazam ex | H7: Local shop | I7: Webster, NY | J7: Vintage | K7: 6 | L7: 6 | M7: 6
A8: White Flare | B8: Poke Ball Tin | C8: Rare | F8: Ascended Heroes Sticker Collection | G8: Alolan Exeggutor ex | H8: Other | I8: Pittsford, NY | J8: Japanese | K8: 7 | L8: 7 | M8: 7
A9: Black Bolt | B9: Tin | C9: ACE SPEC Rare | F9: Ascended Heroes Tech Sticker Collection | G9: Alomomola | I9: Victor, NY | J9: Events and tournaments | K9: 8 | L9: 8 | M9: 8
A10: Destined Rivals | B10: ex Premium Collection | C10: Super Rare | F10: Chaos Rising Booster Bundle | G10: Altaria ex | I10: Buffalo, NY | J10: Trade ins | K10: 9 | L10: 9 | M10: 9
A11: Journey Together | B11: ex Special Collection | C11: Charizard | F11: Chaos Rising ETB | G11: Amarys | I11: Syracuse, NY | J11: Supplies | K11: 10 | L11: 10 | M11: 10
A12: Prismatic Evolutions | B12: ex Box | C12: More than one | F12: Chaos Rising ETB : The First Pack Reality | G12: Amoonguss | I12: Online only | K12: 11 | L12: 11 | M12: 11
A13: Surging Sparks | B13: Collection Box | C13: No hit | F13: Destined Rivals | G13: Applin | K13: 12 | L13: 12 | M13: 12
A14: Stellar Crown | B14: Knock Out Collection | F14: Journey Together Booster Bundle | G14: Arbok | K14: 13 | L14: 13 | M14: 13
A15: Shrouded Fable | B15: Blister | F15: Mega Charizard Y EX Tin | G15: Arcanine ex | K15: 14 | L15: 14 | M15: 14
A16: Twilight Masquerade | B16: Japanese Booster Pack | F16: Mega Emboar ex Box | G16: Archaludon ex | K16: 15 | L16: 15 | M16: 15
A17: Temporal Forces | B17: Korean Booster Pack | F17: Mega Feraligatr ex Box | G17: Archeops | K17: 16 | L17: 16 | M17: 16
A18: Paldean Fates | B18: Chinese Booster Pack | F18: Mega Heroes Mini Tin | G18: Arctibax | K18: 17 | L18: 17 | M18: 17
A19: Paradox Rift | B19: Other | F19: Mega Meganium Box : Where are the hits | G19: Armarouge | K19: 18 | L19: 18 | M19: 18
A20: 151 | F20: Mega Meganium ex Box | G20: Articuno | K20: 19 | L20: 19 | M20: 19
A21: Obsidian Flames | F21: Mega Venusaur ex Premium Collection Opening | G21: Arven's Mabosstiff ex | K21: 20 | L21: 20 | M21: 20
A22: Paldea Evolved | F22: Mega Zygarde ex Premium Collection | G22: Audino | L22: 21 | M22: 21
A23: Scarlet & Violet | F23: Perfect Order 3-Pack Blister | G23: Axew | L23: 22 | M23: 22
A24: Crown Zenith | F24: Perfect Order Booster Bundle | G24: Basic Darkness Energy | L24: 23 | M24: 23
A25: Pokémon GO | F25: Perfect Order ETB | G25: Basic Metal Energy | L25: 24 | M25: 24
A26: Celebrations | F26: Prismatic Evolutions ETB | G26: Basic Water Energy | L26: 25 | M26: 25
A27: Chilling Reign | F27: Prismatic Evolutions Mini Tin | G27: Baxcalibur | L27: 26 | M27: 26
A28: Shining Fates | F28: Prismatic Evolutions Poster Collection | G28: Bewear | L28: 27 | M28: 27
A29: Rebel Clash | F29: Prismatic Evolutions Tech Sticker Collection | G29: Bianca's Devotion | L29: 28 | M29: 28
A30: Abyss Eye (JP) | F30: Trick or Trade BOOster Bundle | G30: Bisharp | L30: 29 | M30: 29
A31: Battle Partners (KR) | F31: Victini Illustration Collection | G31: Blastoise ex | L31: 30 | M31: 30
A32: Clay Burst (KR) | G32: Blaziken | M32: 31
A33: Crimson Haze (KR) | G33: Blaziken V | M33: 32
A34: Cyber Judge (JP) | G34: Blaziken VMAX | M34: 33
A35: Gem Pack Vol. 2 (CN) | G35: Blissey V | M35: 34
A36: Mask of Change (KR) | G36: Blitzle | M36: 35
A37: Mega Brave (JP) | G37: Bloodmoon Ursaluna ex | M37: 36
A38: Mega Symphonia (JP) | G38: Boss's Orders
A39: Nihil Zero (JP) | G39: Boss's Orders (Giovanni)
A40: Ninja Spinner (JP) | G40: Bouffalant ex
...

Sheet Video Log
A1: Video ID | B1: Title | C1: Published | D1: Views | E1: Length | F1: Watch | G1: From Your Title | H1: Product | I1: Pack # | J1: Hit | K1: Hit Info | L1: Sets & Packs | M1: Greatest Hits | N1: Greatest Hits Rank | O1: Playlist To Add | P1: Affiliate Link | Q1: Site Title | R1: Short Description | S1: Feature | T1: Hide | U1: Notes
A2: h5mje3jbD48 | B2: The 9th Pack SAVED the Box! 🐋😱 | C2: 2026-08-20 | D2: 611 | E2: 0:24 | F2: =HYPERLINK("https://youtu.be/h5mje3jbD48","watch") | G2: Pitch Black
A3: _RuAmy2dGL8 | B3: Is Rampardos ex a "Real" Hit? 🦖🤔 | C3: 2026-08-19 | D3: 967 | E3: 0:20 | F3: =HYPERLINK("https://youtu.be/_RuAmy2dGL8","watch") | G3: desc: pack 9 Pitch Black | H3: Sleeved Booster Pack | I3: 9 | J3: No | L3: Pitch Black
A4: iIgTusrqVtg | B4: I Just Pulled a $1,000 Card! 😱🐸 | C4: 2026-08-18 | D4: 1164 | E4: 0:28 | F4: =HYPERLINK("https://youtu.be/iIgTusrqVtg","watch") | G4: desc: #3 pack 3 Chaos Rising | H4: ETB | I4: 3 | J4: Yes | K4: Mega Greninja ex - Hyper Rare - Gold Card | L4: Chaos Rising | M4: Yes | N4: 1
A5: DP8HG31X1rg | B5: Is Pack #13 Actually CURSED? 💀🌑 | C5: 2026-08-17 | D5: 801 | E5: 0:20 | F5: =HYPERLINK("https://youtu.be/DP8HG31X1rg","watch") | G5: title: pack 13 Chaos Rising | H5: Single Booster Pack | I5: 13 | J5: No | L5: Chaos Rising
A6: VZtK6rT7ZTI | B6: Trubbish Food 🗑️🤘 | Pitch Black Pack #8 | C6: 2026-08-16 | D6: 919 | E6: 0:21 | F6: =HYPERLINK("https://youtu.be/VZtK6rT7ZTI","watch") | G6: title: pack 8 Pitch Black | H6: ETB | I6: 8 | J6: No | L6: Pitch Black
A7: E5Wz7X1VMeY | B7: 8 Packs and NO HITS?! 🌑💀 | C7: 2026-08-15 | D7: 793 | E7: 0:19 | F7: =HYPERLINK("https://youtu.be/E5Wz7X1VMeY","watch") | G7: desc: pack 8 Pitch Black | H7: Sleeved Booster Pack | I7: 8 | J7: No | L7: Pitch Black
A8: T2-UqY2ZSOw | B8: The Chaos Rising Struggle is REAL 💀 | C8: 2026-08-14 | D8: 1012 | E8: 0:21 | F8: =HYPERLINK("https://youtu.be/T2-UqY2ZSOw","watch") | G8: desc: pack 2 Chaos Rising | H8: ETB | I8: 2 | J8: No | L8: Chaos Rising
A9: O5WscUY7qZI | B9: The Cutest Pull Ever?! 🐭✨ Chaos Rising | C9: 2026-08-13 | D9: 730 | E9: 0:20 | F9: =HYPERLINK("https://youtu.be/O5WscUY7qZI","watch") | G9: desc: pack 12 Chaos Rising | H9: Single Booster Pack | I9: 12 | J9: Yes | K9: Cinccino ex - Double Black Star - Double Rare | L9: Chaos Rising
A10: IQMn3DNCzik | B10: This ETB is BREAKING me! 🌑💀 | C10: 2026-08-12 | D10: 669 | E10: 0:20 | F10: =HYPERLINK("https://youtu.be/IQMn3DNCzik","watch") | G10: desc: pack 7 Pitch Black | H10: ETB | I10: 7 | J10: No | L10: Pitch Black
A11: 2XdMKde79M8 | B11: Pitch Black is SAVAGE Today! 🌑💀 | C11: 2026-08-11 | D11: 16 | E11: 0:18 | F11: =HYPERLINK("https://youtu.be/2XdMKde79M8","watch") | G11: desc: pack 7 Pitch Black | H11: Single Booster Pack | I11: 7 | J11: No | L11: Pitch Black
A12: RZInASE6x1c | B12: Chaos Rising ETB #3: The First Pack Reality 💀 | C12: 2026-08-10 | D12: 1118 | E12: 0:21 | F12: =HYPERLINK("https://youtu.be/RZInASE6x1c","watch") | G12: title: #3 Chaos Rising | H12: ETB | I12: 1 | J12: No | L12: Chaos Rising
A13: oSPbl9reyIM | B13: The most DISAPPOINTING "Hit" 💀 Pitch Black | C13: 2026-08-09 | D13: 687 | E13: 0:22 | F13: =HYPERLINK("https://youtu.be/oSPbl9reyIM","watch") | G13: desc: pack 6 Pitch Black | H13: ETB | I13: 6 | J13: Yes | K13: Rampardos ex - Double Black Star - Double Rare | L13: Pitch Black
A14: inTMqcQmFhM | B14: Did this Bundle have ANY hits?! 📉💀 | C14: 2026-08-08 | D14: 952 | E14: 0:23 | F14: =HYPERLINK("https://youtu.be/inTMqcQmFhM","watch") | G14: desc: pack 6 Booster Bundle Pitch Black | H14: Booster Bundle | I14: 6 | J14: No | L14: Pitch Black
A15: b8CfpcK7-h0 | B15: Pitch Black is SAVAGE Today! 🌑💀 | C15: 2026-08-07 | D15: 653 | E15: 0:18 | F15: =HYPERLINK("https://youtu.be/b8CfpcK7-h0","watch") | G15: desc: pack 6 Pitch Black | H15: Single Booster Pack | I15: 6 | J15: No | L15: Pitch Black
A16: aa9jzXRFtrg | B16: The Box Ends with a Garbage Rip... 🗑️ | C16: 2026-08-06 | D16: 762 | E16: 0:23 | F16: =HYPERLINK("https://youtu.be/aa9jzXRFtrg","watch") | G16: desc: pack 8 ex Premium Collection Perfect Order | H16: ex Premium Collection Box | I16: 8 | J16: No | L16: Perfect Order
A17: znsnYB6boh4 | B17: Where did the hits go?! 📉 Pitch Black ETB | C17: 2026-08-05 | D17: 774 | E17: 0:22 | F17: =HYPERLINK("https://youtu.be/znsnYB6boh4","watch") | G17: desc: pack 5 Pitch Black | H17: ETB | I17: 5 | J17: No | L17: Pitch Black
A18: 16jOkWyE1Cs | B18: The "Pitch Black" Curse is Real! 🌒💀 | C18: 2026-08-04 | D18: 830 | E18: 0:21 | F18: =HYPERLINK("https://youtu.be/16jOkWyE1Cs","watch") | G18: desc: pack 5 Booster Bundle Pitch Black | H18: Booster Bundle | I18: 5 | J18: No | L18: Pitch Black
A19: LmdyCAqDodM | B19: GOLD STAR IN A SINGLE PACK?! 😱 Bastion IR | C19: 2026-08-03 | D19: 657 | E19: 0:21 | F19: =HYPERLINK("https://youtu.be/LmdyCAqDodM","watch") | G19: desc: pack 5 Pitch Black | H19: Single Booster Pack | I19: 5 | J19: Yes | K19: Bastiodon - Single Gold Star - Illustration Rare | L19: Pitch Black
A20: k6p_6HEntYw | B20: Mega Skarmory ex Double Rare Pull! 🦅 | C20: 2026-08-02 | D20: 882 | E20: 0:22 | F20: =HYPERLINK("https://youtu.be/k6p_6HEntYw","watch") | G20: desc: pack 7 ex Premium Collection Perfect Order | H20: ex Premium Collection Box | I20: 7 | J20: Yes | K20: Mega Skarmory ex - Double Silver Star - Ultra Rare | L20: Perfect Order
A21: ndzNjhARITQ | B21: Toucannon Illustration Rare! 🌴 | Pitch Black ETB | C21: 2026-08-01 | D21: 895 | E21: 0:24 | F21: =HYPERLINK("https://youtu.be/ndzNjhARITQ","watch") | G21: desc: pack 4 Pitch Black | H21: ETB | I21: 4 | J21: Yes | K21: Toucannon - Single Gold Star - Illustration Rare | L21: Pitch Black
A22: fY-u0pxphVo | B22: Is the Pitch Black Bundle a Dud Now? 📉 | C22: 2026-07-31 | D22: 768 | E22: 0:22 | F22: =HYPERLINK("https://youtu.be/fY-u0pxphVo","watch") | G22: desc: pack 4 Booster Bundle Pitch Black | H22: Booster Bundle | I22: 4 | J22: No | L22: Pitch Black
A23: 76ziDoR2YJg | B23: Where is the Mega Darkrai SIR?! 🌒😱 | C23: 2026-07-30 | D23: 843 | E23: 0:18 | F23: =HYPERLINK("https://youtu.be/76ziDoR2YJg","watch") | G23: desc: pack 4 Pitch Black | H23: Single Booster Pack | I23: 4 | J23: No | L23: Pitch Black
A24: 3pUiN-8XkEk | B24: DID WE GET THE ZARD?! 🐉🔥 (Final Pack) | C24: 2026-07-29 | D24: 996 | E24: 0:29 | F24: =HYPERLINK("https://youtu.be/3pUiN-8XkEk","watch") | G24: ex Premium Collection Phantasmal Flames | H24: ex Premium Collection Box | I24: 8 | J24: Yes | K24: Trainer - Dawn - Double Silver Star - Ultra Rare | L24: Phantasmal Flames
A25: 019sIQP5PwA | B25: THE STREAK IS BROKEN! 😱 Mega Floette ex | C25: 2026-07-28 | D25: 997 | E25: 0:25 | F25: =HYPERLINK("https://youtu.be/019sIQP5PwA","watch") | G25: desc: pack 6 ex Premium Collection | H25: ex Premium Collection Box | I25: 6 | J25: Yes | K25: Mega Floette ex - Double Black Star - Double Rare | L25: Chaos Rising
A26: 3dAQ-PS0fpU | B26: Chaos Rising Lived Up To Its Name... 🗑️ | C26: 2026-07-27 | D26: 858 | E26: 0:20 | F26: =HYPERLINK("https://youtu.be/3dAQ-PS0fpU","watch") | G26: Tin Chaos Rising | H26: Mini Tin | I26: 2 | J26: No | L26: Chaos Rising
A27: JfHlnrlX6S0 | B27: THE CURSE IS BROKEN! 😱 Pitch Black Hit! | C27: 2026-07-26 | D27: 34 | E27: 0:22 | F27: =HYPERLINK("https://youtu.be/JfHlnrlX6S0","watch") | G27: desc: pack 3 Booster Bundle Pitch Black | H27: Booster Bundle | I27: 3 | J27: Yes | K27: Rampardos ex - Double Silver Star - Ultra Rare | L27: Pitch Black
A28: vTy3MKGN73k | B28: 0 Hits Left in the ETB?! 😱 | C28: 2026-07-25 | D28: 897 | E28: 0:19 | F28: =HYPERLINK("https://youtu.be/vTy3MKGN73k","watch") | G28: desc: pack 3 Pitch Black | H28: ETB | I28: 3 | J28: No | L28: Pitch Black
A29: 1_ivvCs7Gp4 | B29: Only Garbage Rips? 😬 | Pitch Black Pack #3 | C29: 2026-07-24 | D29: 642 | E29: 0:19 | F29: =HYPERLINK("https://youtu.be/1_ivvCs7Gp4","watch") | G29: title: pack 3 Pitch Black | H29: Single Booster Pack | I29: 3 | J29: No | L29: Pitch Black
A30: R2VxbNMrlXQ | B30: I FOUND AN SIR! 💎 (But Not The Zard...) | C30: 2026-07-23 | D30: 1127 | E30: 0:27 | F30: =HYPERLINK("https://youtu.be/R2VxbNMrlXQ","watch") | G30: desc: pack 7 ex Premium Collection Phantasmal Flames | H30: ex Premium Collection Box | I30: 7 | J30: Yes | K30: Trainer - Dawn - Double Gold Star - Special Illustration Rare | L30: Phantasmal Flames
A31: m41IeIUpqRI | B31: This Mini Tin is GLOWING! ✨ Mega Starmie ex | C31: 2026-07-22 | D31: 693 | E31: 0:20 | F31: =HYPERLINK("https://youtu.be/m41IeIUpqRI","watch") | G31: Tin Perfect Order | H31: Mini Tin | I31: 1 | J31: Yes | K31: Mega Starmie ex - Double Black Star - Double Rare | L31: Perfect Order
A32: LGGJhVyJwDc | B32: Where Did the Hits Go?! 😱 Mega Greninja Box | C32: 2026-07-22 | D32: 592 | E32: 0:20 | F32: =HYPERLINK("https://youtu.be/LGGJhVyJwDc","watch") | G32: desc: pack 5 ex Premium Collection | H32: ex Premium Collection Box | I32: 5 | J32: No | L32: Chaos Rising
A33: SQ-_tTDutFA | B33: Only Garbage Rips? 😬 | Pitch Black Pack #2 | C33: 2026-07-21 | D33: 654 | E33: 0:19 | F33: =HYPERLINK("https://youtu.be/SQ-_tTDutFA","watch") | G33: title: pack 2 Booster Bundle Pitch Black | H33: Sleeved Booster Pack | I33: 2 | J33: No | L33: Pitch Black
A34: 405aRLjbdmM | B34: From First Pack Magic to THIS... 🗑️ | C34: 2026-07-21 | D34: 646 | E34: 0:21 | F34: =HYPERLINK("https://youtu.be/405aRLjbdmM","watch") | G34: desc: pack 2 Pitch Black | H34: ETB | I34: 2 | J34: No | L34: Pitch Black
A35: yrfwnJKXRgo | B35: The Magic is Officially DEAD 💀 Pitch Black | C35: 2026-07-21 | D35: 722 | E35: 0:20 | F35: =HYPERLINK("https://youtu.be/yrfwnJKXRgo","watch") | G35: Booster Bundle Pitch Black | H35: Booster Bundle | I35: 2 | J35: No | L35: Pitch Black
A36: 92-pjMEGpDI | B36: Perfect Order Luck Ran Out... 🗑️ | C36: 2026-07-20 | D36: 820 | E36: 0:22 | F36: =HYPERLINK("https://youtu.be/92-pjMEGpDI","watch") | G36: desc: pack 6 ex Premium Collection Phantasmal Flames | H36: ex Premium Collection Box | I36: 6 | J36: No | L36: Perfect Order
A37: 2S4poqmGKWE | B37: The Tin Luck Finally Ran Out! ❌ | C37: 2026-07-19 | D37: 689 | E37: 0:20 | F37: =HYPERLINK("https://youtu.be/2S4poqmGKWE","watch") | G37: Tin Twilight Masquerade | H37: Poke Ball Tin | I37: 3 | J37: No | L37: Twilight Masquerade
A38: XxYqEIFgWvg | B38: The Mega Greninja Streak is DEAD 💀 | C38: 2026-07-19 | D38: 683 | E38: 0:21 | F38: =HYPERLINK("https://youtu.be/XxYqEIFgWvg","watch") | G38: desc: pack 4 ex Premium Collection Chaos Rising | H38: ex Premium Collection Box | I38: 4 | J38: No | L38: Chaos Rising
A39: q1WTwiauv3w | B39: I Found First Pack Magic! ✨ Pitch Black ETB | C39: 2026-07-18 | D39: 862 | E39: 0:23 | F39: =HYPERLINK("https://youtu.be/q1WTwiauv3w","watch") | G39: desc: pack 1 Pitch Black | H39: ETB | I39: 1 | J39: Yes | K39: Mega Chandelure ex - Double Black Star - Double Rare | L39: Pitch Black
A40: EtFK6nFW6IQ | B40: I Can't Stop Hitting! ✨ Pitch Black Booster Bundle | C40: 2026-07-18 | D40: 832 | E40: 0:22 | F40: =HYPERLINK("https://youtu.be/EtFK6nFW6IQ","watch") | G40: Booster Bundle Pitch Black | H40: Booster Bundle | I40: 1 | J40: Yes | K40: Mega Excadrill ex - Double Black Star - Double Rare | L40: Pitch Black
...

Sheet Set Notes
A1: Set ID | B1: Set Name | C1: Released | D1: Cards | E1: Your rips | F1: Still In Print | G1: Fun Fact 1 | H1: Fun Fact 2
A2: pitch-black | B2: Pitch Black | C2: 2026-07-17 | D2: 120 | E2: 24
A3: chaos-rising | B3: Chaos Rising | C3: 2026-05-22 | D3: 122 | E3: 53
A4: perfect-order | B4: Perfect Order | C4: 2026-03-27 | D4: 124 | E4: 45
A5: ascended-heroes | B5: Ascended Heroes | C5: 2026-01-30 | D5: 295 | E5: 57
A6: phantasmal-flames | B6: Phantasmal Flames | C6: 2025-11-14 | D6: 130 | E6: 17
A7: mega-evolution | B7: Mega Evolution | C7: 2025-09-26 | D7: 188 | E7: 9
A8: white-flare | B8: White Flare | C8: 2025-07-18 | D8: 173 | E8: 0
A9: black-bolt | B9: Black Bolt | C9: 2025-07-18 | D9: 172 | E9: 0
A10: destined-rivals | B10: Destined Rivals | C10: 2025-05-30 | D10: 244 | E10: 15
A11: journey-together | B11: Journey Together | C11: 2025-03-28 | D11: 190 | E11: 15
A12: prismatic-evolutions | B12: Prismatic Evolutions | C12: 2025-01-17 | D12: 180 | E12: 13
A13: surging-sparks | B13: Surging Sparks | C13: 2024-11-08 | D13: 252 | E13: 9
... A29: rebel-clash | B29: Rebel Clash | C29: 2020-05-01 | D29: 209 | E29: 2
A31: These two facts are not in the card database and are not guessed. The set guides omit them until you fill them in.

Sheet Summary
A1: Progress
A3: Videos in the log | B3: =COUNTA('Video Log'!A2:A319)
A4: Product filled in | B4: =COUNTA('Video Log'!H2:H319)
A5: Still missing a product | B5: =COUNTA('Video Log'!A2:A319)-COUNTA('Video Log'!H2:H319)
A6: Sets & Packs filled in | B6: =COUNTA('Video Log'!L2:L319)
A7: Still missing Sets & Packs | B7: =COUNTA('Video Log'!A2:A319)-COUNTA('Video Log'!L2:L319)
A8: Pack number filled in | B8: =COUNTA('Video Log'!I2:I319)
A9: Marked as a hit | B9: =COUNTIF('Video Log'!J2:J319,"Yes")
A10: Hit info written | B10: =COUNTA('Video Log'!K2:K319)
A11: In Greatest Hits | B11: =COUNTIF('Video Log'!M2:M319,"Yes")
A12: Given a rank | B12: =COUNTA('Video Log'!N2:N319)
A15: Counts update as you type. Blank cells are skipped by the import, so a half-filled sheet is fine.

Sheet Chase Cards
A1: Key | B1: Set | C1: Card | D1: Number | E1: Rarity | F1: Raw USD | G1: PSA 10 USD | H1: PSA 10 Checked | I1: PSA 10 Source | J1: Most Wanted | K1: Card Hall of Fame | L1: Pulled On | M1: Pulled In Video | N1: Why I Want It
A2: pitch-black-116 | B2: Pitch Black | C2: Mega Darkrai ex | D2: 116 | E2: Special illustration rare | F2: 249.22 | J2: Yes | K2: No | N2: The one. Pitch Black's chase, and the reason the box keeps getting opened.
A3: pitch-black-120 | B3: Pitch Black | C3: Mega Darkrai ex | D3: 120 | E3: Mega Hyper Rare | F3: 184.94
A4: pitch-black-117 | B4: Pitch Black | C4: Morpeko ex | D4: 117 | E4: Special illustration rare | F4: 94.73
A5: pitch-black-114 | B5: Pitch Black | C5: Mega Zeraora ex | D5: 114 | E5: Special illustration rare | F5: 57.74
A6: pitch-black-115 | B6: Pitch Black | C6: Mega Chandelure ex | D6: 115 | E6: Special illustration rare | F6: 45.46
A7: pitch-black-119 | B7: Pitch Black | C7: Gwynn | D7: 119 | E7: Special illustration rare | F7: 36.78
A8: pitch-black-118 | B8: Pitch Black | C8: Gladion's Final Battle | D8: 118 | E8: Special illustration rare | F8: 29.99
A9: pitch-black-111 | B9: Pitch Black | C9: Misty's Vitality | D9: 111 | E9: Ultra Rare | F9: 21.72
A10: chaos-rising-116 | B10: Chaos Rising | C10: Mega Greninja ex | D10: 116 | E10: Special illustration rare | F10: 208.35 | J10: Yes | K10: No | N10: Chaos Rising's best art, and still hiding.
A11: chaos-rising-122 | B11: Chaos Rising | C11: Mega Greninja ex | D11: 122 | E11: Mega Hyper Rare | F11: 175
A12: chaos-rising-119 | B12: Chaos Rising | C12: Cinccino ex | D12: 119 | E12: Special illustration rare | F12: 56.48
A13: chaos-rising-118 | B13: Chaos Rising | C13: Mega Dragalge ex | D13: 118 | E13: Special illustration rare | F13: 39.98
A14: chaos-rising-117 | B14: Chaos Rising | C14: Mega Floette ex | D14: 117 | E14: Special illustration rare | F14: 31
A15: chaos-rising-120 | B15: Chaos Rising | C15: AZ's Tranquility | D15: 120 | E15: Special illustration rare | F15: 25.28
A16: chaos-rising-121 | B16: Chaos Rising | C16: Roxie's Performance | D16: 121 | E16: Special illustration rare | F16: 21
A17: chaos-rising-100 | B17: Chaos Rising | C17: Mega Greninja ex | D17: 100 | E17: Ultra Rare | F17: 14.76
A18: perfect-order-124 | B18: Perfect Order | C18: Mega Zygarde ex | D18: 124 | E18: Mega Hyper Rare | F18: 120.01
A19: perfect-order-121 | B19: Perfect Order | C19: Meowth ex | D19: 121 | E19: Special illustration rare | F19: 127.59 | J19: Yes | K19: No | N19: Perfect Order's SIR. Pulled everything else in the set except this.
A20: perfect-order-120 | B20: Perfect Order | C20: Mega Zygarde ex | D20: 120 | E20: Special illustration rare | F20: 56.72
A21: perfect-order-119 | B21: Perfect Order | C21: Mega Clefable ex | D21: 119 | E21: Special illustration rare | F21: 50.66
A22: perfect-order-123 | B22: Perfect Order | C22: Rosa's Encouragement | D22: 123 | E22: Special illustration rare | F22: 49.02
A23: perfect-order-118 | B23: Perfect Order | C23: Mega Starmie ex | D23: 118 | E23: Special illustration rare | F23: 42
A24: perfect-order-122 | B24: Perfect Order | C24: Jacinthe | D24: 122 | E24: Special illustration rare | F24: 23.2
A25: perfect-order-094 | B25: Perfect Order | C25: Clefairy | D25: 094 | E25: Illustration rare | F25: 20.29
A26: ascended-heroes-284 | B26: Ascended Heroes | C26: Mega Gengar ex | D26: 284 | E26: Special illustration rare | F26: 1085.48
A27: ascended-heroes-276 | B27: Ascended Heroes | C27: Pikachu ex | D27: 276 | E27: Special illustration rare | F27: 1003.87
A28: ascended-heroes-290 | B28: Ascended Heroes | C28: Mega Dragonite ex | D28: 290 | E28: Special illustration rare | F28: 670 | J28: Yes | K28: No | N28: Ascended Heroes chase. Three Feraligatr boxes deep and still nothing.
A29: ascended-heroes-294 | B29: Ascended Heroes | C29: Mega Charizard Y ex | D29: 294 | E29: Mega Hyper Rare | F29: 354.84
A30: ascended-heroes-277 | B30: Ascended Heroes | C30: Pikachu ex | D30: 277 | E30: Special illustration rare | F30: 358.23
A31: ascended-heroes-281 | B31: Ascended Heroes | C31: Team Rocket's Mewtwo ex | D31: 281 | E31: Special illustration rare | F31: 354.53
A32: ascended-heroes-295 | B32: Ascended Heroes | C32: Mega Dragonite ex | D32: 295 | E32: Mega Hyper Rare | F32: 255.88
A33: ascended-heroes-280 | B33: Ascended Heroes | C33: Lillie's Clefairy ex | D33: 280 | E33: Special illustration rare | F33: 165.51
A34: phantasmal-flames-125 | B34: Phantasmal Flames | C34: Mega Charizard X ex | D34: 125 | E34: Special illustration rare | F34: 750 | J34: Yes | K34: No | N34: The Charizard. Always the Charizard.
A35: phantasmal-flames-130 | B35: Phantasmal Flames | C35: Mega Charizard X ex | D35: 130 | E35: Mega Hyper Rare | F35: 308.02
A36: phantasmal-flames-109 | B36: Phantasmal Flames | C36: Mega Charizard X ex | D36: 109 | E36: Ultra Rare | F36: 28.87
A37: phantasmal-flames-129 | B37: Phantasmal Flames | C37: Dawn | D37: 129 | E37: Special illustration rare | F37: 20.5
A38: phantasmal-flames-127 | B38: Phantasmal Flames | C38: Mega Sharpedo ex | D38: 127 | E38: Special illustration rare | F38: 19.72
A39: phantasmal-flames-106 | B39: Phantasmal Flames | C39: Meowth | D39: 106 | E39: Illustration rare | F39: 18.61
A40: phantasmal-flames-126 | B40: Phantasmal Flames | C40: Rotom ex | D40: 126 | E40: Special illustration rare | F40: 14.32
...

Sheet My Hits
A1: Video ID | B1: Card | C1: Set | D1: Number | E1: Rarity | F1: Raw NM USD | G1: PSA 10 USD | H1: Hall of Fame | I1: Notes
A2: kj7532tb0_I | B2: Dawn | C2: Phantasmal Flames | E2: Ultra Rare
A3: kj7532tb0_I | B3: Mega Gengar ex | C3: Phantasmal Flames | E3: Double Rare
A4: kj7532tb0_I | B4: Mega Gardevoir ex | C4: Mega Evolution | E4: Ultra Rare
A5: kj7532tb0_I | B5: Mega Venusaur ex | C5: Mega Evolution | E5: Double Rare
A6: kj7532tb0_I | B6: Marshadow | C6: Mega Evolution | E6: Illustration Rare
A7: kj7532tb0_I | B7: Cetitan ex | C7: Destined Rivals | E7: Double Rare
A8: kj7532tb0_I | B8: Rotom | C8: Destined Rivals | E8: Illustration Rare
A9: kj7532tb0_I | B9: Noibat | C9: Journey Together | E9: Illustration Rare
A10: kj7532tb0_I | B10: Brock's Scouting | C10: Journey Together | E10: Ultra Rare
A11: kj7532tb0_I | B11: Blaziken ex | C11: Journey Together | E11: Double Rare
A12: kj7532tb0_I | B12: Scramble Switch | C12: Surging Sparks | E12: ACE SPEC Rare
A13: kj7532tb0_I | B13: Cyrano | C13: Surging Sparks | E13: Ultra Rare
A14: kj7532tb0_I | B14: Mega Charizard X ex | C14: MEP Black Star Promos | D14: 023 | E14: Black Star Promo | G14: 176.57
A15: kj7532tb0_I | B15: Oricorio ex | C15: MEP Black Star Promos | D15: 024 | E15: Black Star Promo | G15: 99.78
A16: TN7_ZsuRQSI | B16: Stufful | C16: Mega Evolution | E16: Illustration Rare
A17: TN7_ZsuRQSI | B17: Marnie's Grimmsnarl ex | C17: Destined Rivals | E17: Double Rare
A18: TN7_ZsuRQSI | B18: Wailord | C18: Journey Together | E18: Illustration Rare
A19: iIgTusrqVtg | B19: Mega Greninja ex | C19: Chaos Rising | E19: Hyper Rare
A20: O5WscUY7qZI | B20: Cinccino ex | C20: Chaos Rising | E20: Double Rare
A21: oSPbl9reyIM | B21: Rampardos ex | C21: Pitch Black | E21: Double Rare
A22: LmdyCAqDodM | B22: Bastiodon | C22: Pitch Black | E22: Illustration Rare
A23: k6p_6HEntYw | B23: Mega Skarmory ex | C23: Perfect Order | E23: Ultra Rare
A24: ndzNjhARITQ | B24: Toucannon | C24: Pitch Black | E24: Illustration Rare
A25: 3pUiN-8XkEk | B25: Dawn | C25: Phantasmal Flames | E25: Ultra Rare
A26: 019sIQP5PwA | B26: Mega Floette ex | C26: Chaos Rising | E26: Double Rare
A27: JfHlnrlX6S0 | B27: Rampardos ex | C27: Pitch Black | E27: Ultra Rare
... A41: EOFAhFwJKqw | B41: Tsareena ex | C41: Paradox Rift | E41: Double Rare
A42: l6RPdGNs7uE | B42: Mega Kangakhan ex | E42: Black Star Promo
A43: l6RPdGNs7uE | B43: Spearow | C43: Mega Evolution | E43: Illustration Rare
A44: GTC45Mri_gc | B44: Thievul | C44: Pitch Black | E44: Illustration Rare
A45: pRkDVGXWufQ | B45: Chespin | C45: Chaos Rising | E45: Illustration Rare
A46: X0KK70SjzEM | B46: Sacred Ash | C46: Perfect Order | E46: Ultra Rare
A47: O1hNutypTR8 | B47: Lumiose City | C47: Perfect Order | E47: Ultra Rare
A48: RP08BTumj2U | B48: Ampharos | C48: Chaos Rising | E48: Illustration Rare
A49: nBKJMnw9L2Y | B49: Mega Scrafty ex | C49: Ascended Heroes | E49: Double Rare
A50: 9CpAz0MxnTE | B50: Energy Recycler | C50: Perfect Order | E50: Ultra Rare
A51: gFZ_jiV7DEY | B51: Team Rocket's Transceiver | C51: Ascended Heroes | E51: Ultra Rare
A52: u9zpVOVsWyg | B52: Scorbunny | C52: Ascended Heroes | E52: Illustration Rare
A53: x3gI4dEKNMs | B53: Beedrill ex | C53: Chaos Rising | E53: Double Rare
...

Sheet Shops
A1: Name | B1: Website | C1: Area | D1: What They Are Good For | E1: Blurb | F1: Filmed There
A2: Just Games | B2: https://www.justgamesrochester.com/category/pokemon/ | C2: Panorama Plaza, Penfield | D2: Singles, Sealed product, Organized Play, Prereleases | E2: Rochester's flagship game store and the one with the busiest Pokemon calendar. Prereleases every set, a learn to play session for anyone starting out, and League Challenges and Cups through the year. | F2: No
A3: Millennium Games | B3: https://shop.millenniumgames.com/collections/pokemon-tcg | C3: Jefferson Road, Henrietta | D3: Sealed product, Singles, In store, Organized Play | E3: One of the biggest game stores in the area, with a Pokemon section to match and a sanctioned league of its own. | F3: No
A4: LingSter Games | B4: https://lingstergames.com/collections/pokemon | C4: West Ridge Road, Rochester | D4: Sealed product, Singles, New releases | E4: Deep Pokemon singles and sealed, and the first stop when a set drops. | F4: No
A5: Legacy Games | B5: https://legacygamestore.com/ | C5: Ridge Road, Webster | D5: Singles, Buylist, In store | E5: The Webster one, and the furthest east of these. They run a separate singles storefront alongside the main site, so you can see which Pokemon singles are actually in the case before you make the drive. They buy cards too. | F5: No
A6: Great Lakes Gaming | B6: https://www.glgaminglounges.com/pokemon | C6: South Clinton Avenue, downtown | D6: Sealed product, Organized Play, In store | E6: Not a shop front. It is a gaming lounge on the 22nd floor of an office tower downtown that sells Pokemon packs, Elite Trainer Boxes and booster boxes at the counter and gives Wednesday night over to Pokemon. | F6: No
A7: WeTheHobby | B7: https://www.wethehobby.com/ | C7: Arlington Street, Neighborhood of the Arts | D7: Organized Play, In store | E7: Mostly sports cards, and better known for breaking live online than for a Pokemon singles case. The Arlington Street building is a real shop and lounge you can walk into though, and there is a Pokemon league in it every week. | F7: No
A9: Add a row per shop. Paste the plain page URL: tracking and session parameters are stripped on build, but a clean link is easier to check.
